[2022-04-07 21:59:29] ERROR Error in Creating Source!!!
Traceback (most recent call last):
  File "G:\AdventsProduct\V1.1.0\AFS\ConsolFiles\process\serializers.py", line 46, in create
    os.mkdir(source_path_proper)
FileNotFoundError: [WinError 3] The system cannot find the path specified: 'G:/AdventsProduct/V1.0.0/AFS/Sources/Data/INVOICE_SALARY_REPORT_PM/input/'
[2022-04-07 22:02:09] ERROR Error in Creating Source!!!
Traceback (most recent call last):
  File "G:\AdventsProduct\V1.1.0\AFS\ConsolFiles\process\serializers.py", line 46, in create
    os.mkdir(source_path_proper)
FileNotFoundError: [WinError 3] The system cannot find the path specified: 'G:/AdventsProduct/V1.0.0/AFS/Sources/Data/INVOICE_SALARY_REPORT_PM/input/'
[2022-04-08 22:34:38] ERROR Error in Creating Source!!!
Traceback (most recent call last):
  File "G:\AdventsProduct\V1.1.0\AFS\ConsolFiles\process\serializers.py", line 66, in create
    validated_data.push(source_definitions)
AttributeError: 'dict' object has no attribute 'push'
[2022-04-08 22:40:38] ERROR Error in Creating Source!!!
Traceback (most recent call last):
  File "G:\AdventsProduct\V1.1.0\AFS\ConsolFiles\process\serializers.py", line 65, in create
    return Response(**validated_data)
TypeError: __init__() got an unexpected keyword argument 'tenants_id'
[2022-05-05 07:35:45] ERROR Error in Creating Source!!!
Traceback (most recent call last):
  File "G:\AdventsProduct\V1.1.0\AFS\ConsolFiles\process\serializers.py", line 48, in create
    source_path_proper = source_path.replace("{source_name}", source_name)
UnboundLocalError: local variable 'source_path' referenced before assignment
[2022-05-05 07:45:28] ERROR Error in Creating Source!!!
Traceback (most recent call last):
  File "G:\AdventsProduct\V1.1.0\AFS\ConsolFiles\process\serializers.py", line 50, in create
    source_path_proper = source_path.replace("{source_name}", source_name)
UnboundLocalError: local variable 'source_path' referenced before assignment
[2022-05-05 07:47:26] ERROR Error in Creating Source!!!
Traceback (most recent call last):
  File "G:\AdventsProduct\V1.1.0\AFS\ConsolFiles\process\serializers.py", line 52, in create
    source_path_proper = source_path.replace("{source_name}", source_name)
UnboundLocalError: local variable 'source_path' referenced before assignment
[2022-05-05 07:52:15] ERROR Error in Creating Source!!!
Traceback (most recent call last):
  File "G:\AdventsProduct\V1.1.0\AFS\ConsolFiles\process\serializers.py", line 58, in create
    source_path_proper = source_path.replace("{source_name}", source_name)
UnboundLocalError: local variable 'source_path' referenced before assignment
[2022-05-05 07:56:22] ERROR Error in Creating Source!!!
Traceback (most recent call last):
  File "G:\AdventsProduct\V1.1.0\AFS\ConsolFiles\process\serializers.py", line 58, in create
    source_path_proper = source_path.replace("{source_name}", source_name)
UnboundLocalError: local variable 'source_path' referenced before assignment
[2022-05-05 07:57:18] ERROR Error in Creating Source!!!
Traceback (most recent call last):
  File "G:\AdventsProduct\V1.1.0\AFS\ConsolFiles\process\serializers.py", line 74, in create
    raise serializers.ValidationError({"Status": "Error", "Message": "Source Name Already Exists!!!"})
rest_framework.exceptions.ValidationError: {'Status': ErrorDetail(string='Error', code='invalid'), 'Message': ErrorDetail(string='Source Name Already Exists!!!', code='invalid')}
[2022-05-05 08:00:04] ERROR Error in Creating Source!!!
Traceback (most recent call last):
  File "G:\AdventsProduct\V1.1.0\AFS\ConsolFiles\process\serializers.py", line 74, in create
    raise serializers.ValidationError({"status_code": 405, "detail": "Method 'DELETE' not allowed."})
rest_framework.exceptions.ValidationError: {'status_code': ErrorDetail(string='405', code='invalid'), 'detail': ErrorDetail(string="Method 'DELETE' not allowed.", code='invalid')}
[2022-05-05 08:01:13] ERROR Error in Creating Source!!!
Traceback (most recent call last):
  File "G:\AdventsProduct\V1.1.0\AFS\ConsolFiles\process\serializers.py", line 74, in create
    raise serializers.ValidationError({"status_code": 405, "detail": "Method 'DELETE' not allowed."})
rest_framework.exceptions.ValidationError: {'status_code': ErrorDetail(string='405', code='invalid'), 'detail': ErrorDetail(string="Method 'DELETE' not allowed.", code='invalid')}
[2022-05-08 21:24:09] ERROR Error in File Uploads View Generic
Traceback (most recent call last):
  File "G:\AdventsProduct\V1.1.0\AFS\ConsolFiles\process\views.py", line 98, in get_queryset
    return queryset.filter(tenants_id = tenants_id, groups_id = groups_id, entities_id = entities_id, m_processing_layer_id = m_processing_layer_id, m_processing_sub_layer_id = m_processing_sub_layer_id, processing_layer_id = processing_layer_id, is_active = 1)
  File "C:\Users\user\Envs\django\lib\site-packages\django\db\models\query.py", line 942, in filter
    return self._filter_or_exclude(False, *args, **kwargs)
  File "C:\Users\user\Envs\django\lib\site-packages\django\db\models\query.py", line 962, in _filter_or_exclude
    clone._filter_or_exclude_inplace(negate, *args, **kwargs)
  File "C:\Users\user\Envs\django\lib\site-packages\django\db\models\query.py", line 969, in _filter_or_exclude_inplace
    self._query.add_q(Q(*args, **kwargs))
  File "C:\Users\user\Envs\django\lib\site-packages\django\db\models\sql\query.py", line 1358, in add_q
    clause, _ = self._add_q(q_object, self.used_aliases)
  File "C:\Users\user\Envs\django\lib\site-packages\django\db\models\sql\query.py", line 1377, in _add_q
    child_clause, needed_inner = self.build_filter(
  File "C:\Users\user\Envs\django\lib\site-packages\django\db\models\sql\query.py", line 1258, in build_filter
    lookups, parts, reffed_expression = self.solve_lookup_type(arg)
  File "C:\Users\user\Envs\django\lib\site-packages\django\db\models\sql\query.py", line 1084, in solve_lookup_type
    _, field, _, lookup_parts = self.names_to_path(lookup_splitted, self.get_meta())
  File "C:\Users\user\Envs\django\lib\site-packages\django\db\models\sql\query.py", line 1481, in names_to_path
    raise FieldError("Cannot resolve keyword '%s' into field. "
django.core.exceptions.FieldError: Cannot resolve keyword 'm_processing_layer_id' into field. Choices are: comments, created_by, created_date, entities_id, extraction_type, file_name, file_path, file_row_count, file_size_bytes, groups_id, id, is_active, is_processed, m_sources, m_sources_id, modified_by, modified_date, module_id, source_name, source_type, status, tenants_id
