[2022-08-25 20:20:10] ERROR Error in Upload Files!!!
Traceback (most recent call last):
  File "C:\Users\user\Envs\django\lib\site-packages\django\utils\datastructures.py", line 76, in __getitem__
    list_ = super().__getitem__(key)
KeyError: 'fileName'

During handling of the above exception, another exception occurred:

Traceback (most recent call last):
  File "G:\AdventsProduct\V1.1.0\AFS\ALCSRecon\alcs\views.py", line 357, in get_upload_files
    file_name = request.FILES["fileName"].name
  File "C:\Users\user\Envs\django\lib\site-packages\django\utils\datastructures.py", line 78, in __getitem__
    raise MultiValueDictKeyError(key)
django.utils.datastructures.MultiValueDictKeyError: 'fileName'
[2022-08-25 20:20:29] ERROR Error in Upload Files!!!
Traceback (most recent call last):
  File "C:\Users\user\Envs\django\lib\site-packages\django\utils\datastructures.py", line 76, in __getitem__
    list_ = super().__getitem__(key)
KeyError: 'fileName'

During handling of the above exception, another exception occurred:

Traceback (most recent call last):
  File "G:\AdventsProduct\V1.1.0\AFS\ALCSRecon\alcs\views.py", line 357, in get_upload_files
    file_name = request.FILES["fileName"].name
  File "C:\Users\user\Envs\django\lib\site-packages\django\utils\datastructures.py", line 78, in __getitem__
    raise MultiValueDictKeyError(key)
django.utils.datastructures.MultiValueDictKeyError: 'fileName'
[2022-08-25 20:21:11] ERROR Error in Upload Files!!!
Traceback (most recent call last):
  File "C:\Users\user\Envs\django\lib\site-packages\django\utils\datastructures.py", line 76, in __getitem__
    list_ = super().__getitem__(key)
KeyError: 'fileName'

During handling of the above exception, another exception occurred:

Traceback (most recent call last):
  File "G:\AdventsProduct\V1.1.0\AFS\ALCSRecon\alcs\views.py", line 357, in get_upload_files
    file_name = request.FILES["fileName"].name
  File "C:\Users\user\Envs\django\lib\site-packages\django\utils\datastructures.py", line 78, in __getitem__
    raise MultiValueDictKeyError(key)
django.utils.datastructures.MultiValueDictKeyError: 'fileName'
