[2022-07-25 19:19:30] ERROR Error in Get Daily Letters Report Function!!!
Traceback (most recent call last):
  File "G:\AdventsProduct\V1.1.0\AFS\ALCSRecon\alcs\views.py", line 557, in get_daily_letters_report
    daily_letters_query_common_headers = json.loads(setting.setting_value)
  File "c:\users\user\appdata\local\programs\python\python39\lib\json\__init__.py", line 346, in loads
    return _default_decoder.decode(s)
  File "c:\users\user\appdata\local\programs\python\python39\lib\json\decoder.py", line 337, in decode
    obj, end = self.raw_decode(s, idx=_w(s, 0).end())
  File "c:\users\user\appdata\local\programs\python\python39\lib\json\decoder.py", line 355, in raw_decode
    raise JSONDecodeError("Expecting value", s, err.value) from None
json.decoder.JSONDecodeError: Expecting value: line 1 column 1 (char 0)
[2022-07-25 19:24:10] ERROR Error in Get Daily Letters Report Function!!!
Traceback (most recent call last):
  File "G:\AdventsProduct\V1.1.0\AFS\ALCSRecon\alcs\views.py", line 557, in get_daily_letters_report
    daily_letters_query_common_headers = json.loads(setting.setting_value)
  File "c:\users\user\appdata\local\programs\python\python39\lib\json\__init__.py", line 346, in loads
    return _default_decoder.decode(s)
  File "c:\users\user\appdata\local\programs\python\python39\lib\json\decoder.py", line 337, in decode
    obj, end = self.raw_decode(s, idx=_w(s, 0).end())
  File "c:\users\user\appdata\local\programs\python\python39\lib\json\decoder.py", line 355, in raw_decode
    raise JSONDecodeError("Expecting value", s, err.value) from None
json.decoder.JSONDecodeError: Expecting value: line 1 column 1 (char 0)
[2022-07-25 21:11:46] INFO SELECT int_reference_text_1 as alcs_type, int_extracted_text_50 as date, '' AS re_issue, int_amount_1 AS total, int_generated_num_2 AS letter_number, '' as text_1, '' as text_2, '' as text_3, int_reference_date_time_3 as bank_date, int_extracted_text_6 as bank_description, int_extracted_text_7 as bank_ref_number, int_reference_date_time_4 as bank_clearing_date, int_amount_2 as bank_debit from alcs_recon.daily_letters_view where processing_layer_id = {processing_layer_id} and int_extracted_text_50 = '2022-07-22';SELECT int_reference_text_1 as alcs_type, int_extracted_text_50 as date, '' AS re_issue, int_amount_1 AS total, int_generated_num_2 AS letter_number, '' as text_1, '' as text_2, '' as text_3, int_reference_date_time_3 as bank_date, int_extracted_text_6 as bank_description, int_extracted_text_7 as bank_ref_number, int_reference_date_time_4 as bank_clearing_date, int_amount_2 as bank_debit from alcs_recon.daily_letters_view where int_extracted_text_50 = '2022-07-22';
[2022-07-25 21:11:46] ERROR (1064, "You have an error in your SQL syntax; check the manual that corresponds to your MySQL server version for the right syntax to use near '} and int_extracted_text_50 = '2022-07-22';SELECT int_reference_text_1 as alcs_t' at line 1")
[2022-07-25 21:11:46] ERROR Error in Executing SQL Query
Traceback (most recent call last):
  File "C:\Users\user\Envs\django\lib\site-packages\django\db\backends\utils.py", line 82, in _execute
    return self.cursor.execute(sql)
  File "C:\Users\user\Envs\django\lib\site-packages\django\db\backends\mysql\base.py", line 73, in execute
    return self.cursor.execute(query, args)
  File "C:\Users\user\Envs\django\lib\site-packages\MySQLdb\cursors.py", line 206, in execute
    res = self._query(query)
  File "C:\Users\user\Envs\django\lib\site-packages\MySQLdb\cursors.py", line 319, in _query
    db.query(q)
  File "C:\Users\user\Envs\django\lib\site-packages\MySQLdb\connections.py", line 259, in query
    _mysql.connection.query(self, query)
MySQLdb._exceptions.ProgrammingError: (1064, "You have an error in your SQL syntax; check the manual that corresponds to your MySQL server version for the right syntax to use near '} and int_extracted_text_50 = '2022-07-22';SELECT int_reference_text_1 as alcs_t' at line 1")

The above exception was the direct cause of the following exception:

Traceback (most recent call last):
  File "G:\AdventsProduct\V1.1.0\AFS\ALCSRecon\alcs\views.py", line 34, in execute_sql_query
    cursor.execute(query)
  File "C:\Users\user\Envs\django\lib\site-packages\django\db\backends\utils.py", line 98, in execute
    return super().execute(sql, params)
  File "C:\Users\user\Envs\django\lib\site-packages\django\db\backends\utils.py", line 66, in execute
    return self._execute_with_wrappers(sql, params, many=False, executor=self._execute)
  File "C:\Users\user\Envs\django\lib\site-packages\django\db\backends\utils.py", line 75, in _execute_with_wrappers
    return executor(sql, params, many, context)
  File "C:\Users\user\Envs\django\lib\site-packages\django\db\backends\utils.py", line 84, in _execute
    return self.cursor.execute(sql, params)
  File "C:\Users\user\Envs\django\lib\site-packages\django\db\utils.py", line 90, in __exit__
    raise dj_exc_value.with_traceback(traceback) from exc_value
  File "C:\Users\user\Envs\django\lib\site-packages\django\db\backends\utils.py", line 82, in _execute
    return self.cursor.execute(sql)
  File "C:\Users\user\Envs\django\lib\site-packages\django\db\backends\mysql\base.py", line 73, in execute
    return self.cursor.execute(query, args)
  File "C:\Users\user\Envs\django\lib\site-packages\MySQLdb\cursors.py", line 206, in execute
    res = self._query(query)
  File "C:\Users\user\Envs\django\lib\site-packages\MySQLdb\cursors.py", line 319, in _query
    db.query(q)
  File "C:\Users\user\Envs\django\lib\site-packages\MySQLdb\connections.py", line 259, in query
    _mysql.connection.query(self, query)
django.db.utils.ProgrammingError: (1064, "You have an error in your SQL syntax; check the manual that corresponds to your MySQL server version for the right syntax to use near '} and int_extracted_text_50 = '2022-07-22';SELECT int_reference_text_1 as alcs_t' at line 1")
[2022-07-25 21:11:46] ERROR Error in Get Daily Letters Report Function!!!
Traceback (most recent call last):
  File "G:\AdventsProduct\V1.1.0\AFS\ALCSRecon\alcs\views.py", line 732, in get_daily_letters_report
    daily_letters_report_query_output = json.loads(execute_sql_query(daily_letters_report_query_proper, object_type="table"))
  File "c:\users\user\appdata\local\programs\python\python39\lib\json\__init__.py", line 339, in loads
    raise TypeError(f'the JSON object must be str, bytes or bytearray, '
TypeError: the JSON object must be str, bytes or bytearray, not NoneType
[2022-07-25 21:12:30] INFO SELECT int_reference_text_1 as alcs_type, int_extracted_text_50 as date, '' AS re_issue, int_amount_1 AS total, int_generated_num_2 AS letter_number, '' as text_1, '' as text_2, '' as text_3, int_reference_date_time_3 as bank_date, int_extracted_text_6 as bank_description, int_extracted_text_7 as bank_ref_number, int_reference_date_time_4 as bank_clearing_date, int_amount_2 as bank_debit from alcs_recon.daily_letters_view where processing_layer_id = {processing_layer_id} and int_extracted_text_50 = '2022-07-22';SELECT int_reference_text_1 as alcs_type, int_extracted_text_50 as date, '' AS re_issue, int_amount_1 AS total, int_generated_num_2 AS letter_number, '' as text_1, '' as text_2, '' as text_3, int_reference_date_time_3 as bank_date, int_extracted_text_6 as bank_description, int_extracted_text_7 as bank_ref_number, int_reference_date_time_4 as bank_clearing_date, int_amount_2 as bank_debit from alcs_recon.daily_letters_view where int_extracted_text_50 = '2022-07-22';
[2022-07-25 21:12:30] ERROR (1064, "You have an error in your SQL syntax; check the manual that corresponds to your MySQL server version for the right syntax to use near '} and int_extracted_text_50 = '2022-07-22';SELECT int_reference_text_1 as alcs_t' at line 1")
[2022-07-25 21:12:30] ERROR Error in Executing SQL Query
Traceback (most recent call last):
  File "C:\Users\user\Envs\django\lib\site-packages\django\db\backends\utils.py", line 82, in _execute
    return self.cursor.execute(sql)
  File "C:\Users\user\Envs\django\lib\site-packages\django\db\backends\mysql\base.py", line 73, in execute
    return self.cursor.execute(query, args)
  File "C:\Users\user\Envs\django\lib\site-packages\MySQLdb\cursors.py", line 206, in execute
    res = self._query(query)
  File "C:\Users\user\Envs\django\lib\site-packages\MySQLdb\cursors.py", line 319, in _query
    db.query(q)
  File "C:\Users\user\Envs\django\lib\site-packages\MySQLdb\connections.py", line 259, in query
    _mysql.connection.query(self, query)
MySQLdb._exceptions.ProgrammingError: (1064, "You have an error in your SQL syntax; check the manual that corresponds to your MySQL server version for the right syntax to use near '} and int_extracted_text_50 = '2022-07-22';SELECT int_reference_text_1 as alcs_t' at line 1")

The above exception was the direct cause of the following exception:

Traceback (most recent call last):
  File "G:\AdventsProduct\V1.1.0\AFS\ALCSRecon\alcs\views.py", line 34, in execute_sql_query
    cursor.execute(query)
  File "C:\Users\user\Envs\django\lib\site-packages\django\db\backends\utils.py", line 98, in execute
    return super().execute(sql, params)
  File "C:\Users\user\Envs\django\lib\site-packages\django\db\backends\utils.py", line 66, in execute
    return self._execute_with_wrappers(sql, params, many=False, executor=self._execute)
  File "C:\Users\user\Envs\django\lib\site-packages\django\db\backends\utils.py", line 75, in _execute_with_wrappers
    return executor(sql, params, many, context)
  File "C:\Users\user\Envs\django\lib\site-packages\django\db\backends\utils.py", line 84, in _execute
    return self.cursor.execute(sql, params)
  File "C:\Users\user\Envs\django\lib\site-packages\django\db\utils.py", line 90, in __exit__
    raise dj_exc_value.with_traceback(traceback) from exc_value
  File "C:\Users\user\Envs\django\lib\site-packages\django\db\backends\utils.py", line 82, in _execute
    return self.cursor.execute(sql)
  File "C:\Users\user\Envs\django\lib\site-packages\django\db\backends\mysql\base.py", line 73, in execute
    return self.cursor.execute(query, args)
  File "C:\Users\user\Envs\django\lib\site-packages\MySQLdb\cursors.py", line 206, in execute
    res = self._query(query)
  File "C:\Users\user\Envs\django\lib\site-packages\MySQLdb\cursors.py", line 319, in _query
    db.query(q)
  File "C:\Users\user\Envs\django\lib\site-packages\MySQLdb\connections.py", line 259, in query
    _mysql.connection.query(self, query)
django.db.utils.ProgrammingError: (1064, "You have an error in your SQL syntax; check the manual that corresponds to your MySQL server version for the right syntax to use near '} and int_extracted_text_50 = '2022-07-22';SELECT int_reference_text_1 as alcs_t' at line 1")
[2022-07-25 21:12:30] ERROR Error in Get Daily Letters Report Function!!!
Traceback (most recent call last):
  File "G:\AdventsProduct\V1.1.0\AFS\ALCSRecon\alcs\views.py", line 734, in get_daily_letters_report
    daily_letters_report_query_output = json.loads(execute_sql_query(daily_letters_report_query_proper, object_type="table"))
  File "c:\users\user\appdata\local\programs\python\python39\lib\json\__init__.py", line 339, in loads
    raise TypeError(f'the JSON object must be str, bytes or bytearray, '
TypeError: the JSON object must be str, bytes or bytearray, not NoneType
[2022-07-25 21:21:56] ERROR Error in Get Excel Export Data!!!
Traceback (most recent call last):
  File "G:\AdventsProduct\V1.1.0\AFS\ALCSRecon\alcs\views.py", line 1158, in get_excel_export_data
    field_changed_dict[header['headerName']] = round(float(v), 2)
ValueError: could not convert string to float: ''
[2022-07-25 21:23:51] ERROR Error in Get Excel Export Data!!!
Traceback (most recent call last):
  File "G:\AdventsProduct\V1.1.0\AFS\ALCSRecon\alcs\views.py", line 1158, in get_excel_export_data
    field_changed_dict[header['headerName']] = round(float(v), 2)
ValueError: could not convert string to float: ''
[2022-07-25 21:24:32] ERROR Error in Get Excel Export Data!!!
Traceback (most recent call last):
  File "G:\AdventsProduct\V1.1.0\AFS\ALCSRecon\alcs\views.py", line 1160, in get_excel_export_data
    field_changed_dict[header['headerName']] = round(float(v), 2)
ValueError: could not convert string to float: ''
[2022-07-25 21:27:13] ERROR Error in Get Excel Export Data!!!
Traceback (most recent call last):
  File "G:\AdventsProduct\V1.1.0\AFS\ALCSRecon\alcs\views.py", line 1160, in get_excel_export_data
    field_changed_dict[header['headerName']] = round(float(v), 2)
ValueError: could not convert string to float: ''
[2022-07-25 21:28:39] ERROR Error in Get Excel Export Data!!!
Traceback (most recent call last):
  File "G:\AdventsProduct\V1.1.0\AFS\ALCSRecon\alcs\views.py", line 1162, in get_excel_export_data
    field_changed_dict[header['headerName']] = round(float(v), 2)
ValueError: could not convert string to float: ''
[2022-07-25 21:29:38] ERROR Error in Get Excel Export Data!!!
Traceback (most recent call last):
  File "G:\AdventsProduct\V1.1.0\AFS\ALCSRecon\alcs\views.py", line 1162, in get_excel_export_data
    field_changed_dict[header['headerName']] = round(float(v), 2)
ValueError: could not convert string to float: ''
