[2022-02-03 15:28:17] ERROR Error in Upload Files!!!
Traceback (most recent call last):
  File "C:\Users\user\Envs\django\lib\site-packages\django\utils\datastructures.py", line 76, in __getitem__
    list_ = super().__getitem__(key)
KeyError: 'fileName'

During handling of the above exception, another exception occurred:

Traceback (most recent call last):
  File "G:\AdventsProduct\V1.1.0\AFS\ALCSRecon\alcs\views.py", line 195, in get_upload_files
    internal_file_name = request.FILES["fileName"].name
  File "C:\Users\user\Envs\django\lib\site-packages\django\utils\datastructures.py", line 78, in __getitem__
    raise MultiValueDictKeyError(key)
django.utils.datastructures.MultiValueDictKeyError: 'fileName'
[2022-02-03 15:30:52] ERROR Error in Upload Files!!!
Traceback (most recent call last):
  File "C:\Users\user\Envs\django\lib\site-packages\django\utils\datastructures.py", line 76, in __getitem__
    list_ = super().__getitem__(key)
KeyError: 'fileName'

During handling of the above exception, another exception occurred:

Traceback (most recent call last):
  File "G:\AdventsProduct\V1.1.0\AFS\ALCSRecon\alcs\views.py", line 195, in get_upload_files
    internal_file_name = request.FILES["fileName"].name
  File "C:\Users\user\Envs\django\lib\site-packages\django\utils\datastructures.py", line 78, in __getitem__
    raise MultiValueDictKeyError(key)
django.utils.datastructures.MultiValueDictKeyError: 'fileName'
[2022-02-03 15:31:44] ERROR Error in Upload Files!!!
Traceback (most recent call last):
  File "C:\Users\user\Envs\django\lib\site-packages\django\utils\datastructures.py", line 76, in __getitem__
    list_ = super().__getitem__(key)
KeyError: 'fileName'

During handling of the above exception, another exception occurred:

Traceback (most recent call last):
  File "G:\AdventsProduct\V1.1.0\AFS\ALCSRecon\alcs\views.py", line 195, in get_upload_files
    internal_file_name = request.FILES["fileName"].name
  File "C:\Users\user\Envs\django\lib\site-packages\django\utils\datastructures.py", line 78, in __getitem__
    raise MultiValueDictKeyError(key)
django.utils.datastructures.MultiValueDictKeyError: 'fileName'
[2022-02-03 15:33:44] ERROR Error in Upload Files!!!
Traceback (most recent call last):
  File "C:\Users\user\Envs\django\lib\site-packages\django\utils\datastructures.py", line 76, in __getitem__
    list_ = super().__getitem__(key)
KeyError: 'fileName'

During handling of the above exception, another exception occurred:

Traceback (most recent call last):
  File "G:\AdventsProduct\V1.1.0\AFS\ALCSRecon\alcs\views.py", line 195, in get_upload_files
    internal_file_name = request.FILES["fileName"].name
  File "C:\Users\user\Envs\django\lib\site-packages\django\utils\datastructures.py", line 78, in __getitem__
    raise MultiValueDictKeyError(key)
django.utils.datastructures.MultiValueDictKeyError: 'fileName'
[2022-02-03 15:38:30] ERROR Error in Upload Files!!!
Traceback (most recent call last):
  File "C:\Users\user\Envs\django\lib\site-packages\django\utils\datastructures.py", line 76, in __getitem__
    list_ = super().__getitem__(key)
KeyError: 'fileName'

During handling of the above exception, another exception occurred:

Traceback (most recent call last):
  File "G:\AdventsProduct\V1.1.0\AFS\ALCSRecon\alcs\views.py", line 195, in get_upload_files
    internal_file_name = request.FILES["fileName"].name
  File "C:\Users\user\Envs\django\lib\site-packages\django\utils\datastructures.py", line 78, in __getitem__
    raise MultiValueDictKeyError(key)
django.utils.datastructures.MultiValueDictKeyError: 'fileName'
[2022-02-03 15:38:52] ERROR Error in Upload Files!!!
Traceback (most recent call last):
  File "C:\Users\user\Envs\django\lib\site-packages\django\utils\datastructures.py", line 76, in __getitem__
    list_ = super().__getitem__(key)
KeyError: 'fileName'

During handling of the above exception, another exception occurred:

Traceback (most recent call last):
  File "G:\AdventsProduct\V1.1.0\AFS\ALCSRecon\alcs\views.py", line 195, in get_upload_files
    internal_file_name = request.FILES["fileName"].name
  File "C:\Users\user\Envs\django\lib\site-packages\django\utils\datastructures.py", line 78, in __getitem__
    raise MultiValueDictKeyError(key)
django.utils.datastructures.MultiValueDictKeyError: 'fileName'
[2022-02-03 16:25:21] ERROR Error in Upload Files!!!
Traceback (most recent call last):
  File "C:\Users\user\Envs\django\lib\site-packages\django\utils\datastructures.py", line 76, in __getitem__
    list_ = super().__getitem__(key)
KeyError: 'fileName'

During handling of the above exception, another exception occurred:

Traceback (most recent call last):
  File "G:\AdventsProduct\V1.1.0\AFS\ALCSRecon\alcs\views.py", line 195, in get_upload_files
    internal_file_name = request.FILES["fileName"].name
  File "C:\Users\user\Envs\django\lib\site-packages\django\utils\datastructures.py", line 78, in __getitem__
    raise MultiValueDictKeyError(key)
django.utils.datastructures.MultiValueDictKeyError: 'fileName'
[2022-02-03 16:28:55] ERROR Error in Upload Files!!!
Traceback (most recent call last):
  File "C:\Users\user\Envs\django\lib\site-packages\django\utils\datastructures.py", line 76, in __getitem__
    list_ = super().__getitem__(key)
KeyError: 'fileName'

During handling of the above exception, another exception occurred:

Traceback (most recent call last):
  File "G:\AdventsProduct\V1.1.0\AFS\ALCSRecon\alcs\views.py", line 195, in get_upload_files
    internal_file_name = request.FILES["fileName"].name
  File "C:\Users\user\Envs\django\lib\site-packages\django\utils\datastructures.py", line 78, in __getitem__
    raise MultiValueDictKeyError(key)
django.utils.datastructures.MultiValueDictKeyError: 'fileName'
[2022-02-03 16:31:04] ERROR Error in Upload Files!!!
Traceback (most recent call last):
  File "C:\Users\user\Envs\django\lib\site-packages\django\utils\datastructures.py", line 76, in __getitem__
    list_ = super().__getitem__(key)
KeyError: 'fileName'

During handling of the above exception, another exception occurred:

Traceback (most recent call last):
  File "G:\AdventsProduct\V1.1.0\AFS\ALCSRecon\alcs\views.py", line 195, in get_upload_files
    internal_file_name = request.FILES["fileName"].name
  File "C:\Users\user\Envs\django\lib\site-packages\django\utils\datastructures.py", line 78, in __getitem__
    raise MultiValueDictKeyError(key)
django.utils.datastructures.MultiValueDictKeyError: 'fileName'
