[2022-01-25 15:30:10] INFO CALL alcs_recon.p_0403_data_transfer_bank();
[2022-01-25 15:30:10] ERROR (1292, "Incorrect datetime value: 'Generated On:' for column 'ext_reference_date_time_1' at row 24")
[2022-01-25 15:30:10] ERROR Error in Executing SQL Query
Traceback (most recent call last):
  File "C:\Users\user\Envs\django\lib\site-packages\django\db\backends\utils.py", line 82, in _execute
    return self.cursor.execute(sql)
  File "C:\Users\user\Envs\django\lib\site-packages\django\db\backends\mysql\base.py", line 73, in execute
    return self.cursor.execute(query, args)
  File "C:\Users\user\Envs\django\lib\site-packages\MySQLdb\cursors.py", line 206, in execute
    res = self._query(query)
  File "C:\Users\user\Envs\django\lib\site-packages\MySQLdb\cursors.py", line 319, in _query
    db.query(q)
  File "C:\Users\user\Envs\django\lib\site-packages\MySQLdb\connections.py", line 259, in query
    _mysql.connection.query(self, query)
MySQLdb._exceptions.OperationalError: (1292, "Incorrect datetime value: 'Generated On:' for column 'ext_reference_date_time_1' at row 24")

The above exception was the direct cause of the following exception:

Traceback (most recent call last):
  File "G:\AdventsProduct\V1.1.0\AFS\ALCSRecon\alcs\views.py", line 24, in execute_sql_query
    cursor.execute(query)
  File "C:\Users\user\Envs\django\lib\site-packages\django\db\backends\utils.py", line 98, in execute
    return super().execute(sql, params)
  File "C:\Users\user\Envs\django\lib\site-packages\django\db\backends\utils.py", line 66, in execute
    return self._execute_with_wrappers(sql, params, many=False, executor=self._execute)
  File "C:\Users\user\Envs\django\lib\site-packages\django\db\backends\utils.py", line 75, in _execute_with_wrappers
    return executor(sql, params, many, context)
  File "C:\Users\user\Envs\django\lib\site-packages\django\db\backends\utils.py", line 84, in _execute
    return self.cursor.execute(sql, params)
  File "C:\Users\user\Envs\django\lib\site-packages\django\db\utils.py", line 90, in __exit__
    raise dj_exc_value.with_traceback(traceback) from exc_value
  File "C:\Users\user\Envs\django\lib\site-packages\django\db\backends\utils.py", line 82, in _execute
    return self.cursor.execute(sql)
  File "C:\Users\user\Envs\django\lib\site-packages\django\db\backends\mysql\base.py", line 73, in execute
    return self.cursor.execute(query, args)
  File "C:\Users\user\Envs\django\lib\site-packages\MySQLdb\cursors.py", line 206, in execute
    res = self._query(query)
  File "C:\Users\user\Envs\django\lib\site-packages\MySQLdb\cursors.py", line 319, in _query
    db.query(q)
  File "C:\Users\user\Envs\django\lib\site-packages\MySQLdb\connections.py", line 259, in query
    _mysql.connection.query(self, query)
django.db.utils.OperationalError: (1292, "Incorrect datetime value: 'Generated On:' for column 'ext_reference_date_time_1' at row 24")
